Workbook

Sheet shock_L
J1: L70
B2: Initial (%) | E2: Parameters | F2: Calibrated Values_70 | G2: Calibrated Values_75 | H2: Calibrated Values_80 | J2: shock | K2: new_delta | L2: new_g | M2: new_sigma_KL | N2: new_laborsh | O2: new_r | P2: new_kappa
B3: g | C3: 1.7 | E3: bl | F3: 0.12888889 | G3: 0.336 | H3: 0.76 | J3: 0.2 | K3: =$F$8+($F$8*J3) -> 0.06 | L3: =($F$14*(($F$3-K3*$F$17-$F$15*$F$10)/($F$9-$F$16+1))) -> 0.01591625 | M3: =$F$20*(((L3*$F$21)+$F$10+K3)/((L3*$F$22)+$F$10)) -> 0.66529525 | N3: =((1+M3)^-1) -> 0.60049412 | O3: =(($F$9*L3)+$F$10) -> 0.0748325 | P3: =($F$19*M3)^(1/$F$7) -> 0.89801346
B4: sigma_KL | C4: =(37.4/(100-37.4)) -> 0.59744409 | E4: bk | F4: 0.33333333 | G4: 0.4 | H4: 0.5 | J4: 0.3 | K4: =$F$8+($F$8*J4) -> 0.065 | L4: =($F$14*(($F$3-K4*$F$17-$F$15*$F$10)/($F$9-$F$16+1))) -> 0.015374375 | M4: =$F$20*(((L4*$F$21)+$F$10+K4)/((L4*$F$22)+$F$10)) -> 0.70077464 | N4: =((1+M4)^-1) -> 0.58796737 | O4: =(($F$9*L4)+$F$10) -> 0.07374875 | P4: =($F$19*M4)^(1/$F$7) -> 0.8525481
B5: r | C5: 7.7 | E5: beta | F5: 0.58012489 | G5: 0.56311067 | H5: 0.62384567 | J5: 0.4 | K5: =$F$8+($F$8*J5) -> 0.07 | L5: =($F$14*(($F$3-K5*$F$17-$F$15*$F$10)/($F$9-$F$16+1))) -> 0.0148325 | M5: =$F$20*(((L5*$F$21)+$F$10+K5)/((L5*$F$22)+$F$10)) -> 0.73735414 | N5: =((1+M5)^-1) -> 0.57558789 | O5: =(($F$9*L5)+$F$10) -> 0.072665 | P5: =($F$19*M5)^(1/$F$7) -> 0.81025393
B6: PK/PL | C6: 1 | E6: alpha | F6: 0.53211009 | G6: 0.71186441 | H6: 0.8172043 | J6: 0.5 | K6: =$F$8+($F$8*J6) -> 0.075 | L6: =($F$14*(($F$3-K6*$F$17-$F$15*$F$10)/($F$9-$F$16+1))) -> 0.014290625 | M6: =$F$20*(((L6*$F$21)+$F$10+K6)/((L6*$F$22)+$F$10)) -> 0.77508572 | N6: =((1+M6)^-1) -> 0.56335308 | O6: =(($F$9*L6)+$F$10) -> 0.07158125 | P6: =($F$19*M6)^(1/$F$7) -> 0.77081034
B7: l_h | C7: 12.5 | E7: psi | F7: -1 | G7: -1 | H7: -1 | J7: 0.6 | K7: =$F$8+($F$8*J7) -> 0.08 | L7: =($F$14*(($F$3-K7*$F$17-$F$15*$F$10)/($F$9-$F$16+1))) -> 0.01374875 | M7: =$F$20*(((L7*$F$21)+$F$10+K7)/((L7*$F$22)+$F$10)) -> 0.81402468 | N7: =((1+M7)^-1) -> 0.55126042 | O7: =(($F$9*L7)+$F$10) -> 0.0704975 | P7: =($F$19*M7)^(1/$F$7) -> 0.73393854
B8: l_z | C8: 12.5 | E8: delta | F8: 0.05 | G8: 0.05 | H8: 0.05 | J8: 0.7 | K8: =$F$8+($F$8*J8) -> 0.085 | L8: =($F$14*(($F$3-K8*$F$17-$F$15*$F$10)/($F$9-$F$16+1))) -> 0.013206875 | M8: =$F$20*(((L8*$F$21)+$F$10+K8)/((L8*$F$22)+$F$10)) -> 0.85422992 | N8: =((1+M8)^-1) -> 0.53930745 | O8: =(($F$9*L8)+$F$10) -> 0.06941375 | P8: =($F$19*M8)^(1/$F$7) -> 0.69939495
B9: kappa | C9: 1 | E9: theta | F9: 2 | G9: 2 | H9: 2 | J9: 0.8 | K9: =$F$8+($F$8*J9) -> 0.09 | L9: =($F$14*(($F$3-K9*$F$17-$F$15*$F$10)/($F$9-$F$16+1))) -> 0.012665 | M9: =$F$20*(((L9*$F$21)+$F$10+K9)/((L9*$F$22)+$F$10)) -> 0.89576422 | N9: =((1+M9)^-1) -> 0.52749176 | O9: =(($F$9*L9)+$F$10) -> 0.06833 | P9: =($F$19*M9)^(1/$F$7) -> 0.66696579
B10: gamma | C10: =1-0.374 -> 0.626 | E10: rho | F10: =($C$5-(F9*$C$3))/100 -> 0.043 | G10: =($C$5-(G9*$C$3))/100 -> 0.043 | H10: =($C$5-(H9*$C$3))/100 -> 0.043
J11: L75
J12: shock | K12: new_delta | L12: new_g | M12: new_sigma_KL | N12: new_laborsh | O12: new_r | P12: new_kappa
E13: SS parameter components | J13: 0.2 | K13: =$G$8+($G$8*J13) -> 0.06 | L13: =($G$14*(($G$3-K13*$G$17-$G$15*$G$10)/($G$9-$G$16+1))) -> 0.016239474 | M13: =$G$20*(((L13*$G$21)+$G$10+K13)/((L13*$G$22)+$G$10)) -> 0.66483048 | N13: =((1+M13)^-1) -> 0.60066176 | O13: =(($G$9*L13)+$G$10) -> 0.075478947 | P13: =($G$19*M13)^(1/$G$7) -> 0.89864124
E14: 1-alpha/alpha | F14: =(1-$F$6)/$F$6 -> 0.87931034 | G14: =(1-$G$6)/$G$6 -> 0.4047619 | H14: =(1-$H$6)/$H$6 -> 0.22368421 | J14: 0.3 | K14: =$G$8+($G$8*J14) -> 0.065 | L14: =($G$14*(($G$3-K14*$G$17-$G$15*$G$10)/($G$9-$G$16+1))) -> 0.015859211 | M14: =$G$20*(((L14*$G$21)+$G$10+K14)/((L14*$G$22)+$G$10)) -> 0.69988432 | N14: =((1+M14)^-1) -> 0.58827532 | O14: =(($G$9*L14)+$G$10) -> 0.074718421 | P14: =($G$19*M14)^(1/$G$7) -> 0.85363263
E15: alpha/(1-alpha) | F15: =$F$6/(1-$F$6) -> 1.1372549 | G15: =$G$6/(1-$G$6) -> 2.4705882 | H15: =$H$6/(1-$H$6) -> 4.4705882 | J15: 0.4 | K15: =$G$8+($G$8*J15) -> 0.07 | L15: =($G$14*(($G$3-K15*$G$17-$G$15*$G$10)/($G$9-$G$16+1))) -> 0.015478947 | M15: =$G$20*(((L15*$G$21)+$G$10+K15)/((L15*$G$22)+$G$10)) -> 0.73589476 | N15: =((1+M15)^-1) -> 0.57607179 | O15: =(($G$9*L15)+$G$10) -> 0.073957895 | P15: =($G$19*M15)^(1/$G$7) -> 0.81186077
E16: (1-2alpha)/(1-alpha) | F16: =(1-2*$F$6)/(1-$F$6) -> -0.1372549 | G16: =(1-2*$G$6)/(1-$G$6) -> -1.4705882 | H16: =(1-2*$H$6)/(1-$H$6) -> -3.4705882 | J16: 0.5 | K16: =$G$8+($G$8*J16) -> 0.075 | L16: =($G$14*(($G$3-K16*$G$17-$G$15*$G$10)/($G$9-$G$16+1))) -> 0.015098684 | M16: =$G$20*(((L16*$G$21)+$G$10+K16)/((L16*$G$22)+$G$10)) -> 0.77290151 | N16: =((1+M16)^-1) -> 0.56404713 | O16: =(($G$9*L16)+$G$10) -> 0.073197368 | P16: =($G$19*M16)^(1/$G$7) -> 0.77298865
E17: bl/bk | F17: =$F$3/$F$4 -> 0.38666667 | G17: =$G$3/$G$4 -> 0.84 | H17: =$H$3/$H$4 -> 1.52 | J17: 0.6 | K17: =$G$8+($G$8*J17) -> 0.08 | L17: =($G$14*(($G$3-K17*$G$17-$G$15*$G$10)/($G$9-$G$16+1))) -> 0.014718421 | M17: =$G$20*(((L17*$G$21)+$G$10+K17)/((L17*$G$22)+$G$10)) -> 0.81094648 | N17: =((1+M17)^-1) -> 0.55219743 | O17: =(($G$9*L17)+$G$10) -> 0.072436842 | P17: =($G$19*M17)^(1/$G$7) -> 0.73672444
E18: (1-alpha)/(1-beta) | F18: =(1-$F$6)/(1-$F$5) -> 1.114355 | G18: =(1-$G$6)/(1-$G$5) -> 0.6595162 | H18: =(1-$H$6)/(1-$H$5) -> 0.48595931 | J18: 0.7 | K18: =$G$8+($G$8*J18) -> 0.085 | L18: =($G$14*(($G$3-K18*$G$17-$G$15*$G$10)/($G$9-$G$16+1))) -> 0.014338158 | M18: =$G$20*(((L18*$G$21)+$G$10+K18)/((L18*$G$22)+$G$10)) -> 0.850074 | N18: =((1+M18)^-1) -> 0.54051892 | O18: =(($G$9*L18)+$G$10) -> 0.071676316 | P18: =($G$19*M18)^(1/$G$7) -> 0.70281421
E19: gamma/(1-gamma) | F19: =C10/(1-C10) -> 1.6737968 | G19: =$C$10/(1-$C$10) -> 1.6737968 | H19: =$C$10/(1-$C$10) -> 1.6737968 | J19: 0.8 | K19: =$G$8+($G$8*J19) -> 0.09 | L19: =($G$14*(($G$3-K19*$G$17-$G$15*$G$10)/($G$9-$G$16+1))) -> 0.013957895 | M19: =$G$20*(((L19*$G$21)+$G$10+K19)/((L19*$G$22)+$G$10)) -> 0.89033093 | N19: =((1+M19)^-1) -> 0.5290079 | O19: =(($G$9*L19)+$G$10) -> 0.070915789 | P19: =($G$19*M19)^(1/$G$7) -> 0.67103598
E20: xi | F20: =F18*F17 -> 0.43088392 | G20: =G18*G17 -> 0.55399361 | H20: =H18*H17 -> 0.73865815
E21: (theta-1) | F21: =F9-1 -> 1 | G21: =G9-1 -> 1 | H21: =H9-1 -> 1 | J21: L80
E22: theta-(1-2alpha/1-alpha) | F22: =F9-F16 -> 2.1372549 | G22: =G9-G16 -> 3.4705882 | H22: =H9-H16 -> 5.4705882 | J22: shock | K22: new_delta | L22: new_g | M22: new_sigma_KL | N22: new_laborsh | O22: new_r | P22: new_kappa
J23: 0.2 | K23: =$H$8+($H$8*J23) -> 0.06 | L23: =($H$14*(($H$3-K23*$H$17-$H$15*$H$10)/($H$9-$H$16+1))) -> 0.016474545 | M23: =$H$20*(((L23*$H$21)+$H$10+K23)/((L23*$H$22)+$H$10)) -> 0.66291489 | N23: =((1+M23)^-1) -> 0.60135369 | O23: =(($H$9*L23)+$H$10) -> 0.075949091 | P23: =($H$19*M23)^(1/$H$7) -> 0.901238
J24: 0.3 | K24: =$H$8+($H$8*J24) -> 0.065 | L24: =($H$14*(($H$3-K24*$H$17-$H$15*$H$10)/($H$9-$H$16+1))) -> 0.016211818 | M24: =$H$20*(((L24*$H$21)+$H$10+K24)/((L24*$H$22)+$H$10)) -> 0.69672214 | N24: =((1+M24)^-1) -> 0.58937169 | O24: =(($H$9*L24)+$H$10) -> 0.075423636 | P24: =($H$19*M24)^(1/$H$7) -> 0.85750697
J25: 0.4 | K25: =$H$8+($H$8*J25) -> 0.07 | L25: =($H$14*(($H$3-K25*$H$17-$H$15*$H$10)/($H$9-$H$16+1))) -> 0.015949091 | M25: =$H$20*(((L25*$H$21)+$H$10+K25)/((L25*$H$22)+$H$10)) -> 0.73127548 | N25: =((1+M25)^-1) -> 0.57760883 | O25: =(($H$9*L25)+$H$10) -> 0.074898182 | P25: =($H$19*M25)^(1/$H$7) -> 0.81698909
J26: 0.5 | K26: =$H$8+($H$8*J26) -> 0.075 | L26: =($H$14*(($H$3-K26*$H$17-$H$15*$H$10)/($H$9-$H$16+1))) -> 0.015686364 | M26: =$H$20*(((L26*$H$21)+$H$10+K26)/((L26*$H$22)+$H$10)) -> 0.76659991 | N26: =((1+M26)^-1) -> 0.56605913 | O26: =(($H$9*L26)+$H$10) -> 0.074372727 | P26: =($H$19*M26)^(1/$H$7) -> 0.77934276
J27: 0.6 | K27: =$H$8+($H$8*J27) -> 0.08 | L27: =($H$14*(($H$3-K27*$H$17-$H$15*$H$10)/($H$9-$H$16+1))) -> 0.015423636 | M27: =$H$20*(((L27*$H$21)+$H$10+K27)/((L27*$H$22)+$H$10)) -> 0.80272151 | N27: =((1+M27)^-1) -> 0.55471685 | O27: =(($H$9*L27)+$H$10) -> 0.073847273 | P27: =($H$19*M27)^(1/$H$7) -> 0.74427318
J28: 0.7 | K28: =$H$8+($H$8*J28) -> 0.085 | L28: =($H$14*(($H$3-K28*$H$17-$H$15*$H$10)/($H$9-$H$16+1))) -> 0.015160909 | M28: =$H$20*(((L28*$H$21)+$H$10+K28)/((L28*$H$22)+$H$10)) -> 0.83966758 | N28: =((1+M28)^-1) -> 0.54357646 | O28: =(($H$9*L28)+$H$10) -> 0.073321818 | P28: =($H$19*M28)^(1/$H$7) -> 0.71152454
J29: 0.8 | K29: =$H$8+($H$8*J29) -> 0.09 | L29: =($H$14*(($H$3-K29*$H$17-$H$15*$H$10)/($H$9-$H$16+1))) -> 0.014898182 | M29: =$H$20*(((L29*$H$21)+$H$10+K29)/((L29*$H$22)+$H$10)) -> 0.87746668 | N29: =((1+M29)^-1) -> 0.53263262 | O29: =(($H$9*L29)+$H$10) -> 0.072796364 | P29: =($H$19*M29)^(1/$H$7) -> 0.68087382

Sheet shock_L_theta
J1: L70
B2: Initial (%) | E2: Parameters | F2: Calibrated Values_70 | G2: Calibrated Values_75 | H2: Calibrated Values_80 | J2: shock | K2: new_delta | L2: new_g | M2: new_sigma_KL | N2: new_laborsh | O2: new_r | P2: new_kappa
B3: g | C3: 1.7 | E3: bl | F3: 0.12888889 | G3: 0.336 | H3: 0.76 | J3: 0.2 | K3: =$F$8+($F$8*J3) -> 0.06 | L3: =($F$14*(($F$3-K3*$F$17-$F$15*$F$10)/($F$9-$F$16+1))) -> 0.015710781 | M3: =$F$20*(((L3*$F$21)+$F$10+K3)/((L3*$F$22)+$F$10)) -> 0.66597537 | N3: =((1+M3)^-1) -> 0.60024897 | O3: =(($F$9*L3)+$F$10) -> 0.075066171 | P3: =($F$19*M3)^(1/$F$7) -> 0.89709637
B4: sigma_KL | C4: 0.59744409 | E4: bk | F4: 0.33333333 | G4: 0.4 | H4: 0.5 | J4: 0.3 | K4: =$F$8+($F$8*J4) -> 0.065 | L4: =($F$14*(($F$3-K4*$F$17-$F$15*$F$10)/($F$9-$F$16+1))) -> 0.015066171 | M4: =$F$20*(((L4*$F$21)+$F$10+K4)/((L4*$F$22)+$F$10)) -> 0.70166539 | N4: =((1+M4)^-1) -> 0.5876596 | O4: =(($F$9*L4)+$F$10) -> 0.074099257 | P4: =($F$19*M4)^(1/$F$7) -> 0.8514658
B5: r | C5: 7.7 | E5: beta | F5: 0.58012489 | G5: 0.56311067 | H5: 0.62384567 | J5: 0.4 | K5: =$F$8+($F$8*J5) -> 0.07 | L5: =($F$14*(($F$3-K5*$F$17-$F$15*$F$10)/($F$9-$F$16+1))) -> 0.014421561 | M5: =$F$20*(((L5*$F$21)+$F$10+K5)/((L5*$F$22)+$F$10)) -> 0.73835837 | N5: =((1+M5)^-1) -> 0.57525538 | O5: =(($F$9*L5)+$F$10) -> 0.073132342 | P5: =($F$19*M5)^(1/$F$7) -> 0.80915191
B6: PK/PL | C6: 1 | E6: alpha | F6: 0.53211009 | G6: 0.71186441 | H6: 0.8172043 | J6: 0.5 | K6: =$F$8+($F$8*J6) -> 0.075 | L6: =($F$14*(($F$3-K6*$F$17-$F$15*$F$10)/($F$9-$F$16+1))) -> 0.013776952 | M6: =$F$20*(((L6*$F$21)+$F$10+K6)/((L6*$F$22)+$F$10)) -> 0.77609718 | N6: =((1+M6)^-1) -> 0.56303225 | O6: =(($F$9*L6)+$F$10) -> 0.072165428 | P6: =($F$19*M6)^(1/$F$7) -> 0.76980577
B7: l_h | C7: 12.5 | E7: psi | F7: -1 | G7: -1 | H7: -1 | J7: 0.6 | K7: =$F$8+($F$8*J7) -> 0.08 | L7: =($F$14*(($F$3-K7*$F$17-$F$15*$F$10)/($F$9-$F$16+1))) -> 0.013132342 | M7: =$F$20*(((L7*$F$21)+$F$10+K7)/((L7*$F$22)+$F$10)) -> 0.81492719 | N7: =((1+M7)^-1) -> 0.55098629 | O7: =(($F$9*L7)+$F$10) -> 0.071198513 | P7: =($F$19*M7)^(1/$F$7) -> 0.73312573
B8: l_z | C8: 12.5 | E8: delta | F8: 0.05 | G8: 0.05 | H8: 0.05 | J8: 0.7 | K8: =$F$8+($F$8*J8) -> 0.085 | L8: =($F$14*(($F$3-K8*$F$17-$F$15*$F$10)/($F$9-$F$16+1))) -> 0.012487732 | M8: =$F$20*(((L8*$F$21)+$F$10+K8)/((L8*$F$22)+$F$10)) -> 0.85489642 | N8: =((1+M8)^-1) -> 0.53911366 | O8: =(($F$9*L8)+$F$10) -> 0.070231599 | P8: =($F$19*M8)^(1/$F$7) -> 0.69884968
B9: kappa | C9: 1 | E9: theta | F9: 1.5 | G9: 1.5 | H9: 1.5 | J9: 0.8 | K9: =$F$8+($F$8*J9) -> 0.09 | L9: =($F$14*(($F$3-K9*$F$17-$F$15*$F$10)/($F$9-$F$16+1))) -> 0.011843123 | M9: =$F$20*(((L9*$F$21)+$F$10+K9)/((L9*$F$22)+$F$10)) -> 0.89605574 | N9: =((1+M9)^-1) -> 0.52741066 | O9: =(($F$9*L9)+$F$10) -> 0.069264684 | P9: =($F$19*M9)^(1/$F$7) -> 0.6667488
B10: gamma | C10: 0.626 | E10: rho | F10: =($C$5-(F9*$C$3))/100 -> 0.0515 | G10: =($C$5-(G9*$C$3))/100 -> 0.0515 | H10: =($C$5-(H9*$C$3))/100 -> 0.0515
J11: L75
J12: shock | K12: new_delta | L12: new_g | M12: new_sigma_KL | N12: new_laborsh | O12: new_r | P12: new_kappa
E13: SS parameter components | J13: 0.2 | K13: =$G$8+($G$8*J13) -> 0.06 | L13: =($G$14*(($G$3-K13*$G$17-$G$15*$G$10)/($G$9-$G$16+1))) -> 0.016143704 | M13: =$G$20*(((L13*$G$21)+$G$10+K13)/((L13*$G$22)+$G$10)) -> 0.66604171 | N13: =((1+M13)^-1) -> 0.60022507 | O13: =(($G$9*L13)+$G$10) -> 0.075715556 | P13: =($G$19*M13)^(1/$G$7) -> 0.89700702
E14: 1-alpha/alpha | F14: =(1-$F$6)/$F$6 -> 0.87931034 | G14: =(1-$G$6)/$G$6 -> 0.4047619 | H14: =(1-$H$6)/$H$6 -> 0.22368421 | J14: 0.3 | K14: =$G$8+($G$8*J14) -> 0.065 | L14: =($G$14*(($G$3-K14*$G$17-$G$15*$G$10)/($G$9-$G$16+1))) -> 0.015715556 | M14: =$G$20*(((L14*$G$21)+$G$10+K14)/((L14*$G$22)+$G$10)) -> 0.70167341 | N14: =((1+M14)^-1) -> 0.58765683 | O14: =(($G$9*L14)+$G$10) -> 0.075073333 | P14: =($G$19*M14)^(1/$G$7) -> 0.85145607
E15: alpha/(1-alpha) | F15: =$F$6/(1-$F$6) -> 1.1372549 | G15: =$G$6/(1-$G$6) -> 2.4705882 | H15: =$H$6/(1-$H$6) -> 4.4705882 | J15: 0.4 | K15: =$G$8+($G$8*J15) -> 0.07 | L15: =($G$14*(($G$3-K15*$G$17-$G$15*$G$10)/($G$9-$G$16+1))) -> 0.015287407 | M15: =$G$20*(((L15*$G$21)+$G$10+K15)/((L15*$G$22)+$G$10)) -> 0.73824035 | N15: =((1+M15)^-1) -> 0.57529443 | O15: =(($G$9*L15)+$G$10) -> 0.074431111 | P15: =($G$19*M15)^(1/$G$7) -> 0.80928127
E16: (1-2alpha)/(1-alpha) | F16: =(1-2*$F$6)/(1-$F$6) -> -0.1372549 | G16: =(1-2*$G$6)/(1-$G$6) -> -1.4705882 | H16: =(1-2*$H$6)/(1-$H$6) -> -3.4705882 | J16: 0.5 | K16: =$G$8+($G$8*J16) -> 0.075 | L16: =($G$14*(($G$3-K16*$G$17-$G$15*$G$10)/($G$9-$G$16+1))) -> 0.014859259 | M16: =$G$20*(((L16*$G$21)+$G$10+K16)/((L16*$G$22)+$G$10)) -> 0.77577985 | N16: =((1+M16)^-1) -> 0.56313287 | O16: =(($G$9*L16)+$G$10) -> 0.073788889 | P16: =($G$19*M16)^(1/$G$7) -> 0.77012066
E17: bl/bk | F17: =$F$3/$F$4 -> 0.38666667 | G17: =$G$3/$G$4 -> 0.84 | H17: =$H$3/$H$4 -> 1.52 | J17: 0.6 | K17: =$G$8+($G$8*J17) -> 0.08 | L17: =($G$14*(($G$3-K17*$G$17-$G$15*$G$10)/($G$9-$G$16+1))) -> 0.014431111 | M17: =$G$20*(((L17*$G$21)+$G$10+K17)/((L17*$G$22)+$G$10)) -> 0.81433121 | N17: =((1+M17)^-1) -> 0.55116728 | O17: =(($G$9*L17)+$G$10) -> 0.073146667 | P17: =($G$19*M17)^(1/$G$7) -> 0.73366228
E18: (1-alpha)/(1-beta) | F18: =(1-$F$6)/(1-$F$5) -> 1.114355 | G18: =(1-$G$6)/(1-$G$5) -> 0.6595162 | H18: =(1-$H$6)/(1-$H$5) -> 0.48595931 | J18: 0.7 | K18: =$G$8+($G$8*J18) -> 0.085 | L18: =($G$14*(($G$3-K18*$G$17-$G$15*$G$10)/($G$9-$G$16+1))) -> 0.014002963 | M18: =$G$20*(((L18*$G$21)+$G$10+K18)/((L18*$G$22)+$G$10)) -> 0.85393592 | N18: =((1+M18)^-1) -> 0.53939297 | O18: =(($G$9*L18)+$G$10) -> 0.072504444 | P18: =($G$19*M18)^(1/$G$7) -> 0.69963574
E19: gamma/(1-gamma) | F19: =C10/(1-C10) -> 1.6737968 | G19: =$C$10/(1-$C$10) -> 1.6737968 | H19: =$C$10/(1-$C$10) -> 1.6737968 | J19: 0.8 | K19: =$G$8+($G$8*J19) -> 0.09 | L19: =($G$14*(($G$3-K19*$G$17-$G$15*$G$10)/($G$9-$G$16+1))) -> 0.013574815 | M19: =$G$20*(((L19*$G$21)+$G$10+K19)/((L19*$G$22)+$G$10)) -> 0.89463774 | N19: =((1+M19)^-1) -> 0.52780538 | O19: =(($G$9*L19)+$G$10) -> 0.071862222 | P19: =($G$19*M19)^(1/$G$7) -> 0.6678056
E20: xi | F20: =F18*F17 -> 0.43088392 | G20: =G18*G17 -> 0.55399361 | H20: =H18*H17 -> 0.73865815
E21: (theta-1) | F21: =F9-1 -> 0.5 | G21: =G9-1 -> 0.5 | H21: =H9-1 -> 0.5 | J21: L80
E22: theta-(1-2alpha/1-alpha) | F22: =F9-F16 -> 1.6372549 | G22: =G9-G16 -> 2.9705882 | H22: =H9-H16 -> 4.9705882 | J22: shock | K22: new_delta | L22: new_g | M22: new_sigma_KL | N22: new_laborsh | O22: new_r | P22: new_kappa
J23: 0.2 | K23: =$H$8+($H$8*J23) -> 0.06 | L23: =($H$14*(($H$3-K23*$H$17-$H$15*$H$10)/($H$9-$H$16+1))) -> 0.016430542 | M23: =$H$20*(((L23*$H$21)+$H$10+K23)/((L23*$H$22)+$H$10)) -> 0.66403109 | N23: =((1+M23)^-1) -> 0.60095031 | O23: =(($H$9*L23)+$H$10) -> 0.076145813 | P23: =($H$19*M23)^(1/$H$7) -> 0.89972307
J24: 0.3 | K24: =$H$8+($H$8*J24) -> 0.065 | L24: =($H$14*(($H$3-K24*$H$17-$H$15*$H$10)/($H$9-$H$16+1))) -> 0.016145813 | M24: =$H$20*(((L24*$H$21)+$H$10+K24)/((L24*$H$22)+$H$10)) -> 0.69839748 | N24: =((1+M24)^-1) -> 0.58879032 | O24: =(($H$9*L24)+$H$10) -> 0.075718719 | P24: =($H$19*M24)^(1/$H$7) -> 0.85544995
J25: 0.4 | K25: =$H$8+($H$8*J25) -> 0.07 | L25: =($H$14*(($H$3-K25*$H$17-$H$15*$H$10)/($H$9-$H$16+1))) -> 0.015861084 | M25: =$H$20*(((L25*$H$21)+$H$10+K25)/((L25*$H$22)+$H$10)) -> 0.7335102 | N25: =((1+M25)^-1) -> 0.57686422 | O25: =(($H$9*L25)+$H$10) -> 0.075291626 | P25: =($H$19*M25)^(1/$H$7) -> 0.81450005
J26: 0.5 | K26: =$H$8+($H$8*J26) -> 0.075 | L26: =($H$14*(($H$3-K26*$H$17-$H$15*$H$10)/($H$9-$H$16+1))) -> 0.015576355 | M26: =$H$20*(((L26*$H$21)+$H$10+K26)/((L26*$H$22)+$H$10)) -> 0.76939382 | N26: =((1+M26)^-1) -> 0.56516531 | O26: =(($H$9*L26)+$H$10) -> 0.074864532 | P26: =($H$19*M26)^(1/$H$7) -> 0.77651272
J27: 0.6 | K27: =$H$8+($H$8*J27) -> 0.08 | L27: =($H$14*(($H$3-K27*$H$17-$H$15*$H$10)/($H$9-$H$16+1))) -> 0.015291626 | M27: =$H$20*(((L27*$H$21)+$H$10+K27)/((L27*$H$22)+$H$10)) -> 0.80607402 | N27: =((1+M27)^-1) -> 0.55368716 | O27: =(($H$9*L27)+$H$10) -> 0.074437438 | P27: =($H$19*M27)^(1/$H$7) -> 0.7411777
J28: 0.7 | K28: =$H$8+($H$8*J28) -> 0.085 | L28: =($H$14*(($H$3-K28*$H$17-$H$15*$H$10)/($H$9-$H$16+1))) -> 0.015006897 | M28: =$H$20*(((L28*$H$21)+$H$10+K28)/((L28*$H$22)+$H$10)) -> 0.84357762 | N28: =((1+M28)^-1) -> 0.54242359 | O28: =(($H$9*L28)+$H$10) -> 0.074010345 | P28: =($H$19*M28)^(1/$H$7) -> 0.70822658
J29: 0.8 | K29: =$H$8+($H$8*J29) -> 0.09 | L29: =($H$14*(($H$3-K29*$H$17-$H$15*$H$10)/($H$9-$H$16+1))) -> 0.014722167 | M29: =$H$20*(((L29*$H$21)+$H$10+K29)/((L29*$H$22)+$H$10)) -> 0.88193266 | N29: =((1+M29)^-1) -> 0.53136864 | O29: =(($H$9*L29)+$H$10) -> 0.073583251 | P29: =($H$19*M29)^(1/$H$7) -> 0.67742597

Sheet shock_L_psi
J1: L70
B2: Initial (%) | E2: Parameters | F2: Calibrated Values_70 | G2: Calibrated Values_75 | H2: Calibrated Values_80 | J2: shock | K2: new_delta | L2: new_g | M2: new_sigma_KL | N2: new_laborsh | O2: new_r | P2: new_kappa
B3: gamma | C3: 1.7 | E3: bl | F3: 0.12888889 | G3: 0.336 | H3: 0.76 | J3: 0.2 | K3: =$F$8+($F$8*J3) -> 0.06 | L3: =($F$14*(($F$3-K3*$F$17-$F$15*$F$10)/($F$9-$F$16+1))) -> 0.01591625 | M3: =$F$20*(((L3*$F$21)+$F$10+K3)/((L3*$F$22)+$F$10)) -> 0.66529525 | N3: =((1+M3)^-1) -> 0.60049412 | O3: =(($F$9*L3)+$F$10) -> 0.0748325 | P3: =($F$19*M3)^(1/$F$7) -> 0.85167305
B4: sigma_KL | C4: 0.59744409 | E4: bk | F4: 0.33333333 | G4: 0.4 | H4: 0.5 | J4: 0.3 | K4: =$F$8+($F$8*J4) -> 0.065 | L4: =($F$14*(($F$3-K4*$F$17-$F$15*$F$10)/($F$9-$F$16+1))) -> 0.015374375 | M4: =$F$20*(((L4*$F$21)+$F$10+K4)/((L4*$F$22)+$F$10)) -> 0.70077464 | N4: =((1+M4)^-1) -> 0.58796737 | O4: =(($F$9*L4)+$F$10) -> 0.07374875 | P4: =($F$19*M4)^(1/$F$7) -> 0.78812547
B5: r | C5: 7.7 | E5: beta | F5: 0.58012489 | G5: 0.56311067 | H5: 0.62384567 | J5: 0.4 | K5: =$F$8+($F$8*J5) -> 0.07 | L5: =($F$14*(($F$3-K5*$F$17-$F$15*$F$10)/($F$9-$F$16+1))) -> 0.0148325 | M5: =$F$20*(((L5*$F$21)+$F$10+K5)/((L5*$F$22)+$F$10)) -> 0.73735414 | N5: =((1+M5)^-1) -> 0.57558789 | O5: =(($F$9*L5)+$F$10) -> 0.072665 | P5: =($F$19*M5)^(1/$F$7) -> 0.73048895
B6: PK/PL | C6: 1 | E6: alpha | F6: 0.53211009 | G6: 0.71186441 | H6: 0.8172043 | J6: 0.5 | K6: =$F$8+($F$8*J6) -> 0.075 | L6: =($F$14*(($F$3-K6*$F$17-$F$15*$F$10)/($F$9-$F$16+1))) -> 0.014290625 | M6: =$F$20*(((L6*$F$21)+$F$10+K6)/((L6*$F$22)+$F$10)) -> 0.77508572 | N6: =((1+M6)^-1) -> 0.56335308 | O6: =(($F$9*L6)+$F$10) -> 0.07158125 | P6: =($F$19*M6)^(1/$F$7) -> 0.67805508
B7: l_h | C7: 12.5 | E7: psi | F7: -0.67 | G7: -0.67 | H7: -0.67 | J7: 0.6 | K7: =$F$8+($F$8*J7) -> 0.08 | L7: =($F$14*(($F$3-K7*$F$17-$F$15*$F$10)/($F$9-$F$16+1))) -> 0.01374875 | M7: =$F$20*(((L7*$F$21)+$F$10+K7)/((L7*$F$22)+$F$10)) -> 0.81402468 | N7: =((1+M7)^-1) -> 0.55126042 | O7: =(($F$9*L7)+$F$10) -> 0.0704975 | P7: =($F$19*M7)^(1/$F$7) -> 0.63021986
B8: l_z | C8: 12.5 | E8: delta | F8: 0.05 | G8: 0.05 | H8: 0.05 | J8: 0.7 | K8: =$F$8+($F$8*J8) -> 0.085 | L8: =($F$14*(($F$3-K8*$F$17-$F$15*$F$10)/($F$9-$F$16+1))) -> 0.013206875 | M8: =$F$20*(((L8*$F$21)+$F$10+K8)/((L8*$F$22)+$F$10)) -> 0.85422992 | N8: =((1+M8)^-1) -> 0.53930745 | O8: =(($F$9*L8)+$F$10) -> 0.06941375 | P8: =($F$19*M8)^(1/$F$7) -> 0.58646557
B9: kappa | C9: 1 | E9: theta | F9: 2 | G9: 2 | H9: 2 | J9: 0.8 | K9: =$F$8+($F$8*J9) -> 0.09 | L9: =($F$14*(($F$3-K9*$F$17-$F$15*$F$10)/($F$9-$F$16+1))) -> 0.012665 | M9: =$F$20*(((L9*$F$21)+$F$10+K9)/((L9*$F$22)+$F$10)) -> 0.89576422 | N9: =((1+M9)^-1) -> 0.52749176 | O9: =(($F$9*L9)+$F$10) -> 0.06833 | P9: =($F$19*M9)^(1/$F$7) -> 0.54634629
B10: gamma | C10: 0.626 | E10: rho | F10: =($C$5-(F9*$C$3))/100 -> 0.043 | G10: =($C$5-(G9*$C$3))/100 -> 0.043 | H10: =($C$5-(H9*$C$3))/100 -> 0.043
J11: L75
J12: shock | K12: new_delta | L12: new_g | M12: new_sigma_KL | N12: new_laborsh | O12: new_r | P12: new_kappa
E13: SS parameter components | J13: 0.2 | K13: =$G$8+($G$8*J13) -> 0.06 | L13: =($G$14*(($G$3-K13*$G$17-$G$15*$G$10)/($G$9-$G$16+1))) -> 0.016239474 | M13: =$G$20*(((L13*$G$21)+$G$10+K13)/((L13*$G$22)+$G$10)) -> 0.66483048 | N13: =((1+M13)^-1) -> 0.60066176 | O13: =(($G$9*L13)+$G$10) -> 0.075478947 | P13: =($G$19*M13)^(1/$G$7) -> 0.85256184
E14: 1-alpha/alpha | F14: =(1-$F$6)/$F$6 -> 0.87931034 | G14: =(1-$G$6)/$G$6 -> 0.4047619 | H14: =(1-$H$6)/$H$6 -> 0.22368421 | J14: 0.3 | K14: =$G$8+($G$8*J14) -> 0.065 | L14: =($G$14*(($G$3-K14*$G$17-$G$15*$G$10)/($G$9-$G$16+1))) -> 0.015859211 | M14: =$G$20*(((L14*$G$21)+$G$10+K14)/((L14*$G$22)+$G$10)) -> 0.69988432 | N14: =((1+M14)^-1) -> 0.58827532 | O14: =(($G$9*L14)+$G$10) -> 0.074718421 | P14: =($G$19*M14)^(1/$G$7) -> 0.78962231
E15: alpha/(1-alpha) | F15: =$F$6/(1-$F$6) -> 1.1372549 | G15: =$G$6/(1-$G$6) -> 2.4705882 | H15: =$H$6/(1-$H$6) -> 4.4705882 | J15: 0.4 | K15: =$G$8+($G$8*J15) -> 0.07 | L15: =($G$14*(($G$3-K15*$G$17-$G$15*$G$10)/($G$9-$G$16+1))) -> 0.015478947 | M15: =$G$20*(((L15*$G$21)+$G$10+K15)/((L15*$G$22)+$G$10)) -> 0.73589476 | N15: =((1+M15)^-1) -> 0.57607179 | O15: =(($G$9*L15)+$G$10) -> 0.073957895 | P15: =($G$19*M15)^(1/$G$7) -> 0.73265218
E16: (1-2alpha)/(1-alpha) | F16: =(1-2*$F$6)/(1-$F$6) -> -0.1372549 | G16: =(1-2*$G$6)/(1-$G$6) -> -1.4705882 | H16: =(1-2*$H$6)/(1-$H$6) -> -3.4705882 | J16: 0.5 | K16: =$G$8+($G$8*J16) -> 0.075 | L16: =($G$14*(($G$3-K16*$G$17-$G$15*$G$10)/($G$9-$G$16+1))) -> 0.015098684 | M16: =$G$20*(((L16*$G$21)+$G$10+K16)/((L16*$G$22)+$G$10)) -> 0.77290151 | N16: =((1+M16)^-1) -> 0.56404713 | O16: =(($G$9*L16)+$G$10) -> 0.073197368 | P16: =($G$19*M16)^(1/$G$7) -> 0.68091704
E17: bl/bk | F17: =$F$3/$F$4 -> 0.38666667 | G17: =$G$3/$G$4 -> 0.84 | H17: =$H$3/$H$4 -> 1.52 | J17: 0.6 | K17: =$G$8+($G$8*J17) -> 0.08 | L17: =($G$14*(($G$3-K17*$G$17-$G$15*$G$10)/($G$9-$G$16+1))) -> 0.014718421 | M17: =$G$20*(((L17*$G$21)+$G$10+K17)/((L17*$G$22)+$G$10)) -> 0.81094648 | N17: =((1+M17)^-1) -> 0.55219743 | O17: =(($G$9*L17)+$G$10) -> 0.072436842 | P17: =($G$19*M17)^(1/$G$7) -> 0.63379364
E18: (1-alpha)/(1-beta) | F18: =(1-$F$6)/(1-$F$5) -> 1.114355 | G18: =(1-$G$6)/(1-$G$5) -> 0.6595162 | H18: =(1-$H$6)/(1-$H$5) -> 0.48595931 | J18: 0.7 | K18: =$G$8+($G$8*J18) -> 0.085 | L18: =($G$14*(($G$3-K18*$G$17-$G$15*$G$10)/($G$9-$G$16+1))) -> 0.014338158 | M18: =$G$20*(((L18*$G$21)+$G$10+K18)/((L18*$G$22)+$G$10)) -> 0.850074 | N18: =((1+M18)^-1) -> 0.54051892 | O18: =(($G$9*L18)+$G$10) -> 0.071676316 | P18: =($G$19*M18)^(1/$G$7) -> 0.59075008
E19: gamma/(1-gamma) | F19: =C10/(1-C10) -> 1.6737968 | G19: =$C$10/(1-$C$10) -> 1.6737968 | H19: =$C$10/(1-$C$10) -> 1.6737968 | J19: 0.8 | K19: =$G$8+($G$8*J19) -> 0.09 | L19: =($G$14*(($G$3-K19*$G$17-$G$15*$G$10)/($G$9-$G$16+1))) -> 0.013957895 | M19: =$G$20*(((L19*$G$21)+$G$10+K19)/((L19*$G$22)+$G$10)) -> 0.89033093 | N19: =((1+M19)^-1) -> 0.5290079 | O19: =(($G$9*L19)+$G$10) -> 0.070915789 | P19: =($G$19*M19)^(1/$G$7) -> 0.55133004
E20: xi | F20: =F18*F17 -> 0.43088392 | G20: =G18*G17 -> 0.55399361 | H20: =H18*H17 -> 0.73865815
E21: (theta-1) | F21: =F9-1 -> 1 | G21: =G9-1 -> 1 | H21: =H9-1 -> 1 | J21: L80
E22: theta-(1-2alpha/1-alpha) | F22: =F9-F16 -> 2.1372549 | G22: =G9-G16 -> 3.4705882 | H22: =H9-H16 -> 5.4705882 | J22: shock | K22: new_delta | L22: new_g | M22: new_sigma_KL | N22: new_laborsh | O22: new_r | P22: new_kappa
J23: 0.2 | K23: =$H$8+($H$8*J23) -> 0.06 | L23: =($H$14*(($H$3-K23*$H$17-$H$15*$H$10)/($H$9-$H$16+1))) -> 0.016474545 | M23: =$H$20*(((L23*$H$21)+$H$10+K23)/((L23*$H$22)+$H$10)) -> 0.66291489 | N23: =((1+M23)^-1) -> 0.60135369 | O23: =(($H$9*L23)+$H$10) -> 0.075949091 | P23: =($H$19*M23)^(1/$H$7) -> 0.85624147
J24: 0.3 | K24: =$H$8+($H$8*J24) -> 0.065 | L24: =($H$14*(($H$3-K24*$H$17-$H$15*$H$10)/($H$9-$H$16+1))) -> 0.016211818 | M24: =$H$20*(((L24*$H$21)+$H$10+K24)/((L24*$H$22)+$H$10)) -> 0.69672214 | N24: =((1+M24)^-1) -> 0.58937169 | O24: =(($H$9*L24)+$H$10) -> 0.075423636 | P24: =($H$19*M24)^(1/$H$7) -> 0.79497728
J25: 0.4 | K25: =$H$8+($H$8*J25) -> 0.07 | L25: =($H$14*(($H$3-K25*$H$17-$H$15*$H$10)/($H$9-$H$16+1))) -> 0.015949091 | M25: =$H$20*(((L25*$H$21)+$H$10+K25)/((L25*$H$22)+$H$10)) -> 0.73127548 | N25: =((1+M25)^-1) -> 0.57760883 | O25: =(($H$9*L25)+$H$10) -> 0.074898182 | P25: =($H$19*M25)^(1/$H$7) -> 0.73957034
J26: 0.5 | K26: =$H$8+($H$8*J26) -> 0.075 | L26: =($H$14*(($H$3-K26*$H$17-$H$15*$H$10)/($H$9-$H$16+1))) -> 0.015686364 | M26: =$H$20*(((L26*$H$21)+$H$10+K26)/((L26*$H$22)+$H$10)) -> 0.76659991 | N26: =((1+M26)^-1) -> 0.56605913 | O26: =(($H$9*L26)+$H$10) -> 0.074372727 | P26: =($H$19*M26)^(1/$H$7) -> 0.68928806
J27: 0.6 | K27: =$H$8+($H$8*J27) -> 0.08 | L27: =($H$14*(($H$3-K27*$H$17-$H$15*$H$10)/($H$9-$H$16+1))) -> 0.015423636 | M27: =$H$20*(((L27*$H$21)+$H$10+K27)/((L27*$H$22)+$H$10)) -> 0.80272151 | N27: =((1+M27)^-1) -> 0.55471685 | O27: =(($H$9*L27)+$H$10) -> 0.073847273 | P27: =($H$19*M27)^(1/$H$7) -> 0.6435107
J28: 0.7 | K28: =$H$8+($H$8*J28) -> 0.085 | L28: =($H$14*(($H$3-K28*$H$17-$H$15*$H$10)/($H$9-$H$16+1))) -> 0.015160909 | M28: =$H$20*(((L28*$H$21)+$H$10+K28)/((L28*$H$22)+$H$10)) -> 0.83966758 | N28: =((1+M28)^-1) -> 0.54357646 | O28: =(($H$9*L28)+$H$10) -> 0.073321818 | P28: =($H$19*M28)^(1/$H$7) -> 0.60171091
J29: 0.8 | K29: =$H$8+($H$8*J29) -> 0.09 | L29: =($H$14*(($H$3-K29*$H$17-$H$15*$H$10)/($H$9-$H$16+1))) -> 0.014898182 | M29: =$H$20*(((L29*$H$21)+$H$10+K29)/((L29*$H$22)+$H$10)) -> 0.87746668 | N29: =((1+M29)^-1) -> 0.53263262 | O29: =(($H$9*L29)+$H$10) -> 0.072796364 | P29: =($H$19*M29)^(1/$H$7) -> 0.56343747

Sheet shock_delta
J1: L70
B2: Initial (%) | E2: Parameters | F2: Calibrated Values_70 | G2: Calibrated Values_75 | H2: Calibrated Values_80 | J2: shock | K2: new_delta | L2: new_g | M2: new_sigma_KL | N2: new_laborsh | O2: new_r | P2: new_kappa
B3: g | C3: 1.7 | E3: bl | F3: 0.12888889 | G3: 0.336 | H3: 0.76 | J3: 0.2 | K3: =$F$8+($F$8*J3) -> 0.03 | L3: =($F$14*(($F$3-K3*$F$17-$F$15*$F$10)/($F$9-$F$16+1))) -> 0.01591625 | M3: =$F$20*(((L3*$F$21)+$F$10+K3)/((L3*$F$22)+$F$10)) -> 0.64376612 | N3: =((1+M3)^-1) -> 0.60835905 | O3: =(($F$9*L3)+$F$10) -> 0.0748325 | P3: =($F$19*M3)^(1/$F$7) -> 0.92804525
B4: sigma_KL | C4: 0.59744409 | E4: bk | F4: 0.16666667 | G4: 0.2 | H4: 0.25 | J4: 0.3 | K4: =$F$8+($F$8*J4) -> 0.0325 | L4: =($F$14*(($F$3-K4*$F$17-$F$15*$F$10)/($F$9-$F$16+1))) -> 0.015374375 | M4: =$F$20*(((L4*$F$21)+$F$10+K4)/((L4*$F$22)+$F$10)) -> 0.66798792 | N4: =((1+M4)^-1) -> 0.59952473 | O4: =(($F$9*L4)+$F$10) -> 0.07374875 | P4: =($F$19*M4)^(1/$F$7) -> 0.89439356
B5: r | C5: 7.7 | E5: beta | F5: 0.35110211 | G5: 0.3248074 | H5: 0.41867058 | J5: 0.4 | K5: =$F$8+($F$8*J5) -> 0.035 | L5: =($F$14*(($F$3-K5*$F$17-$F$15*$F$10)/($F$9-$F$16+1))) -> 0.0148325 | M5: =$F$20*(((L5*$F$21)+$F$10+K5)/((L5*$F$22)+$F$10)) -> 0.69296076 | N5: =((1+M5)^-1) -> 0.59068114 | O5: =(($F$9*L5)+$F$10) -> 0.072665 | P5: =($F$19*M5)^(1/$F$7) -> 0.8621615
B6: PK/PL | C6: 1 | E6: alpha | F6: 0.53211009 | G6: 0.71186441 | H6: 0.8172043 | J6: 0.5 | K6: =$F$8+($F$8*J6) -> 0.0375 | L6: =($F$14*(($F$3-K6*$F$17-$F$15*$F$10)/($F$9-$F$16+1))) -> 0.014290625 | M6: =$F$20*(((L6*$F$21)+$F$10+K6)/((L6*$F$22)+$F$10)) -> 0.71872014 | N6: =((1+M6)^-1) -> 0.58182829 | O6: =(($F$9*L6)+$F$10) -> 0.07158125 | P6: =($F$19*M6)^(1/$F$7) -> 0.8312611
B7: l_h | C7: 12.5 | E7: psi | F7: -1 | G7: -1 | H7: -1 | J7: 0.6 | K7: =$F$8+($F$8*J7) -> 0.04 | L7: =($F$14*(($F$3-K7*$F$17-$F$15*$F$10)/($F$9-$F$16+1))) -> 0.01374875 | M7: =$F$20*(((L7*$F$21)+$F$10+K7)/((L7*$F$22)+$F$10)) -> 0.74530379 | N7: =((1+M7)^-1) -> 0.57296615 | O7: =(($F$9*L7)+$F$10) -> 0.0704975 | P7: =($F$19*M7)^(1/$F$7) -> 0.8016115
B8: l_z | C8: 12.5 | E8: delta | F8: 0.025 | G8: 0.025 | H8: 0.025 | J8: 0.7 | K8: =$F$8+($F$8*J8) -> 0.0425 | L8: =($F$14*(($F$3-K8*$F$17-$F$15*$F$10)/($F$9-$F$16+1))) -> 0.013206875 | M8: =$F$20*(((L8*$F$21)+$F$10+K8)/((L8*$F$22)+$F$10)) -> 0.77275193 | N8: =((1+M8)^-1) -> 0.56409472 | O8: =(($F$9*L8)+$F$10) -> 0.06941375 | P8: =($F$19*M8)^(1/$F$7) -> 0.77313827
B9: kappa | C9: 1 | E9: theta | F9: 2 | G9: 2 | H9: 2 | J9: 0.8 | K9: =$F$8+($F$8*J9) -> 0.045 | L9: =($F$14*(($F$3-K9*$F$17-$F$15*$F$10)/($F$9-$F$16+1))) -> 0.012665 | M9: =$F$20*(((L9*$F$21)+$F$10+K9)/((L9*$F$22)+$F$10)) -> 0.80110742 | N9: =((1+M9)^-1) -> 0.55521397 | O9: =(($F$9*L9)+$F$10) -> 0.06833 | P9: =($F$19*M9)^(1/$F$7) -> 0.74577275
B10: gamma | C10: 0.626 | E10: rho | F10: =($C$5-(F9*$C$3))/100 -> 0.043 | G10: =($C$5-(G9*$C$3))/100 -> 0.043 | H10: =($C$5-(H9*$C$3))/100 -> 0.043
J11: L75
J12: shock | K12: new_delta | L12: new_g | M12: new_sigma_KL | N12: new_laborsh | O12: new_r | P12: new_kappa
E13: SS parameter components | J13: 0.2 | K13: =$G$8+($G$8*J13) -> 0.03 | L13: =($G$14*(($G$3-K13*$G$17-$G$15*$G$10)/($G$9-$G$16+1))) -> 0.016239474 | M13: =$G$20*(((L13*$G$21)+$G$10+K13)/((L13*$G$22)+$G$10)) -> 0.64390475 | N13: =((1+M13)^-1) -> 0.60830775 | O13: =(($G$9*L13)+$G$10) -> 0.075478947 | P13: =($G$19*M13)^(1/$G$7) -> 0.92784544
E14: 1-alpha/alpha | F14: =(1-$F$6)/$F$6 -> 0.87931034 | G14: =(1-$G$6)/$G$6 -> 0.4047619 | H14: =(1-$H$6)/$H$6 -> 0.22368421 | J14: 0.3 | K14: =$G$8+($G$8*J14) -> 0.0325 | L14: =($G$14*(($G$3-K14*$G$17-$G$15*$G$10)/($G$9-$G$16+1))) -> 0.015859211 | M14: =$G$20*(((L14*$G$21)+$G$10+K14)/((L14*$G$22)+$G$10)) -> 0.6680732 | N14: =((1+M14)^-1) -> 0.59949407 | O14: =(($G$9*L14)+$G$10) -> 0.074718421 | P14: =($G$19*M14)^(1/$G$7) -> 0.89427938
E15: alpha/(1-alpha) | F15: =$F$6/(1-$F$6) -> 1.1372549 | G15: =$G$6/(1-$G$6) -> 2.4705882 | H15: =$H$6/(1-$H$6) -> 4.4705882 | J15: 0.4 | K15: =$G$8+($G$8*J15) -> 0.035 | L15: =($G$14*(($G$3-K15*$G$17-$G$15*$G$10)/($G$9-$G$16+1))) -> 0.015478947 | M15: =$G$20*(((L15*$G$21)+$G$10+K15)/((L15*$G$22)+$G$10)) -> 0.6929012 | N15: =((1+M15)^-1) -> 0.59070193 | O15: =(($G$9*L15)+$G$10) -> 0.073957895 | P15: =($G$19*M15)^(1/$G$7) -> 0.86223561
E16: (1-2alpha)/(1-alpha) | F16: =(1-2*$F$6)/(1-$F$6) -> -0.1372549 | G16: =(1-2*$G$6)/(1-$G$6) -> -1.4705882 | H16: =(1-2*$H$6)/(1-$H$6) -> -3.4705882 | J16: 0.5 | K16: =$G$8+($G$8*J16) -> 0.0375 | L16: =($G$14*(($G$3-K16*$G$17-$G$15*$G$10)/($G$9-$G$16+1))) -> 0.015098684 | M16: =$G$20*(((L16*$G$21)+$G$10+K16)/((L16*$G$22)+$G$10)) -> 0.71841611 | N16: =((1+M16)^-1) -> 0.58193123 | O16: =(($G$9*L16)+$G$10) -> 0.073197368 | P16: =($G$19*M16)^(1/$G$7) -> 0.83161287
E17: bl/bk | F17: =$F$3/$F$4 -> 0.77333333 | G17: =$G$3/$G$4 -> 1.68 | H17: =$H$3/$H$4 -> 3.04 | J17: 0.6 | K17: =$G$8+($G$8*J17) -> 0.04 | L17: =($G$14*(($G$3-K17*$G$17-$G$15*$G$10)/($G$9-$G$16+1))) -> 0.014718421 | M17: =$G$20*(((L17*$G$21)+$G$10+K17)/((L17*$G$22)+$G$10)) -> 0.74464685 | N17: =((1+M17)^-1) -> 0.5731819 | O17: =(($G$9*L17)+$G$10) -> 0.072436842 | P17: =($G$19*M17)^(1/$G$7) -> 0.80231869
E18: (1-alpha)/(1-beta) | F18: =(1-$F$6)/(1-$F$5) -> 0.72105321 | G18: =(1-$G$6)/(1-$G$5) -> 0.42674578 | H18: =(1-$H$6)/(1-$H$5) -> 0.31444426 | J18: 0.7 | K18: =$G$8+($G$8*J18) -> 0.0425 | L18: =($G$14*(($G$3-K18*$G$17-$G$15*$G$10)/($G$9-$G$16+1))) -> 0.014338158 | M18: =$G$20*(((L18*$G$21)+$G$10+K18)/((L18*$G$22)+$G$10)) -> 0.77162397 | N18: =((1+M18)^-1) -> 0.56445387 | O18: =(($G$9*L18)+$G$10) -> 0.071676316 | P18: =($G$19*M18)^(1/$G$7) -> 0.77426844
E19: gamma/(1-gamma) | F19: =C10/(1-C10) -> 1.6737968 | G19: =$C$10/(1-$C$10) -> 1.6737968 | H19: =$C$10/(1-$C$10) -> 1.6737968 | J19: 0.8 | K19: =$G$8+($G$8*J19) -> 0.045 | L19: =($G$14*(($G$3-K19*$G$17-$G$15*$G$10)/($G$9-$G$16+1))) -> 0.013957895 | M19: =$G$20*(((L19*$G$21)+$G$10+K19)/((L19*$G$22)+$G$10)) -> 0.79937978 | N19: =((1+M19)^-1) -> 0.55574705 | O19: =(($G$9*L19)+$G$10) -> 0.070915789 | P19: =($G$19*M19)^(1/$G$7) -> 0.74738454
E20: xi | F20: =F18*F17 -> 0.55761448 | G20: =G18*G17 -> 0.71693291 | H20: =H18*H17 -> 0.95591054
E21: (theta-1) | F21: =F9-1 -> 1 | G21: =G9-1 -> 1 | H21: =H9-1 -> 1 | J21: L80
E22: theta-(1-2alpha/1-alpha) | F22: =F9-F16 -> 2.1372549 | G22: =G9-G16 -> 3.4705882 | H22: =H9-H16 -> 5.4705882 | J22: shock | K22: new_delta | L22: new_g | M22: new_sigma_KL | N22: new_laborsh | O22: new_r | P22: new_kappa
J23: 0.2 | K23: =$H$8+($H$8*J23) -> 0.03 | L23: =($H$14*(($H$3-K23*$H$17-$H$15*$H$10)/($H$9-$H$16+1))) -> 0.016474545 | M23: =$H$20*(((L23*$H$21)+$H$10+K23)/((L23*$H$22)+$H$10)) -> 0.64247414 | N23: =((1+M23)^-1) -> 0.60883759 | O23: =(($H$9*L23)+$H$10) -> 0.075949091 | P23: =($H$19*M23)^(1/$H$7) -> 0.9299115
J24: 0.3 | K24: =$H$8+($H$8*J24) -> 0.0325 | L24: =($H$14*(($H$3-K24*$H$17-$H$15*$H$10)/($H$9-$H$16+1))) -> 0.016211818 | M24: =$H$20*(((L24*$H$21)+$H$10+K24)/((L24*$H$22)+$H$10)) -> 0.66572636 | N24: =((1+M24)^-1) -> 0.6003387 | O24: =(($H$9*L24)+$H$10) -> 0.075423636 | P24: =($H$19*M24)^(1/$H$7) -> 0.89743193
J25: 0.4 | K25: =$H$8+($H$8*J25) -> 0.035 | L25: =($H$14*(($H$3-K25*$H$17-$H$15*$H$10)/($H$9-$H$16+1))) -> 0.015949091 | M25: =$H$20*(((L25*$H$21)+$H$10+K25)/((L25*$H$22)+$H$10)) -> 0.68949174 | N25: =((1+M25)^-1) -> 0.59189398 | O25: =(($H$9*L25)+$H$10) -> 0.074898182 | P25: =($H$19*M25)^(1/$H$7) -> 0.86649926
J26: 0.5 | K26: =$H$8+($H$8*J26) -> 0.0375 | L26: =($H$14*(($H$3-K26*$H$17-$H$15*$H$10)/($H$9-$H$16+1))) -> 0.015686364 | M26: =$H$20*(((L26*$H$21)+$H$10+K26)/((L26*$H$22)+$H$10)) -> 0.71378747 | N26: =((1+M26)^-1) -> 0.58350293 | O26: =(($H$9*L26)+$H$10) -> 0.074372727 | P26: =($H$19*M26)^(1/$H$7) -> 0.83700558
J27: 0.6 | K27: =$H$8+($H$8*J27) -> 0.04 | L27: =($H$14*(($H$3-K27*$H$17-$H$15*$H$10)/($H$9-$H$16+1))) -> 0.015423636 | M27: =$H$20*(((L27*$H$21)+$H$10+K27)/((L27*$H$22)+$H$10)) -> 0.73863148 | N27: =((1+M27)^-1) -> 0.57516502 | O27: =(($H$9*L27)+$H$10) -> 0.073847273 | P27: =($H$19*M27)^(1/$H$7) -> 0.80885273
J28: 0.7 | K28: =$H$8+($H$8*J28) -> 0.0425 | L28: =($H$14*(($H$3-K28*$H$17-$H$15*$H$10)/($H$9-$H$16+1))) -> 0.015160909 | M28: =$H$20*(((L28*$H$21)+$H$10+K28)/((L28*$H$22)+$H$10)) -> 0.76404255 | N28: =((1+M28)^-1) -> 0.56687975 | O28: =(($H$9*L28)+$H$10) -> 0.073321818 | P28: =($H$19*M28)^(1/$H$7) -> 0.78195133
J29: 0.8 | K29: =$H$8+($H$8*J29) -> 0.045 | L29: =($H$14*(($H$3-K29*$H$17-$H$15*$H$10)/($H$9-$H$16+1))) -> 0.014898182 | M29: =$H$20*(((L29*$H$21)+$H$10+K29)/((L29*$H$22)+$H$10)) -> 0.79004032 | N29: =((1+M29)^-1) -> 0.55864663 | O29: =(($H$9*L29)+$H$10) -> 0.072796364 | P29: =($H$19*M29)^(1/$H$7) -> 0.75621974

Sheet MATLAB_data
C1: BASELINE | O1: theta=1.5 | AA1: psi=-0.67 | AM1: delta=0.025
A2: initials | C2: g1_70 | D2: g2_75 | E2: g3_80 | F2: laborsh_70 | G2: laborsh_75 | H2: laborlsh_80 | I2: r_70 | J2: r_75 | K2: r_80 | L2: kappa_70 | M2: kappa_75 | N2: kappa_80 | O2: g1_70 | P2: g2_75 | Q2: g3_80 | R2: laborsh_70 | S2: laborsh_75 | T2: laborlsh_80 | U2: r_70 | V2: r_75 | W2: r_80 | X2: kappa_70 | Y2: kappa_75 | Z2: kappa_79 | AA2: g1_70 | AB2: g2_75 | AC2: g3_80 | AD2: laborsh_70 | AE2: laborsh_75 | AF2: laborlsh_80 | AG2: r_70 | AH2: r_75 | AI2: r_80 | AJ2: kappa_70 | AK2: kappa_75 | AL2: kappa_80 | AM2: g1_70 | AN2: g2_75 | AO2: g3_80 | AP2: laborsh_70 | AQ2: laborsh_75 | AR2: laborlsh_80 | AS2: r_70 | AT2: r_75 | AU2: r_80 | AV2: kappa_70 | AW2: kappa_75 | AX2: kappa_80
A3: 0.017 | C3: =shock_L!L3 -> 0.01591625 | D3: =shock_L!L13 -> 0.016239474 | E3: =shock_L!L23 -> 0.016474545 | F3: =shock_L!N3 -> 0.60049412 | G3: =shock_L!N13 -> 0.60066176 | H3: =shock_L!N23 -> 0.60135369 | I3: =shock_L!O3 -> 0.0748325 | J3: =shock_L!O13 -> 0.075478947 | K3: =shock_L!O23 -> 0.075949091 | L3: =shock_L!P3 -> 0.89801346 | M3: =shock_L!P13 -> 0.89864124 | N3: =shock_L!P23 -> 0.901238 | O3: =shock_L_theta!L3 -> 0.015710781 | P3: =shock_L_theta!L13 -> 0.016143704 | Q3: =shock_L_theta!L23 -> 0.016430542 | R3: =shock_L_theta!N3 -> 0.60024897 | S3: =shock_L_theta!N13 -> 0.60022507 | T3: =shock_L_theta!N23 -> 0.60095031 | U3: =shock_L_theta!O3 -> 0.075066171 | V3: =shock_L_theta!O13 -> 0.075715556 | W3: =shock_L_theta!O23 -> 0.076145813 | X3: =shock_L_theta!P3 -> 0.89709637 | Y3: =shock_L_theta!P13 -> 0.89700702 | Z3: =shock_L_theta!P23 -> 0.89972307 | AA3: =shock_L_psi!L3 -> 0.01591625 | AB3: =shock_L_psi!L13 -> 0.016239474 | AC3: =shock_L_psi!L23 -> 0.016474545 | AD3: =shock_L_psi!N3 -> 0.60049412 | AE3: =shock_L_psi!N13 -> 0.60066176 | AF3: =shock_L_psi!N23 -> 0.60135369 | AG3: =shock_L_psi!O3 -> 0.0748325 | AH3: =shock_L_psi!O13 -> 0.075478947 | AI3: =shock_L_psi!O23 -> 0.075949091 | AJ3: =shock_L_psi!P3 -> 0.85167305 | AK3: =shock_L_psi!P13 -> 0.85256184 | AL3: =shock_L_psi!P23 -> 0.85624147 | AM3: =shock_delta!L3 -> 0.01591625 | AN3: =shock_delta!L13 -> 0.016239474 | AO3: =shock_delta!L23 -> 0.016474545 | AP3: =shock_delta!N3 -> 0.60835905 | AQ3: =shock_delta!N13 -> 0.60830775 | AR3: =shock_delta!N23 -> 0.60883759 | AS3: =shock_delta!O3 -> 0.0748325 | AT3: =shock_delta!O13 -> 0.075478947 | AU3: =shock_delta!O23 -> 0.075949091 | AV3: =shock_delta!P3 -> 0.92804525 | AW3: =shock_delta!P13 -> 0.92784544 | AX3: =shock_delta!P23 -> 0.9299115
A4: =1-0.374 -> 0.626 | C4: =shock_L!L4 -> 0.015374375 | D4: =shock_L!L14 -> 0.015859211 | E4: =shock_L!L24 -> 0.016211818 | F4: =shock_L!N4 -> 0.58796737 | G4: =shock_L!N14 -> 0.58827532 | H4: =shock_L!N24 -> 0.58937169 | I4: =shock_L!O4 -> 0.07374875 | J4: =shock_L!O14 -> 0.074718421 | K4: =shock_L!O24 -> 0.075423636 | L4: =shock_L!P4 -> 0.8525481 | M4: =shock_L!P14 -> 0.85363263 | N4: =shock_L!P24 -> 0.85750697 | O4: =shock_L_theta!L4 -> 0.015066171 | P4: =shock_L_theta!L14 -> 0.015715556 | Q4: =shock_L_theta!L24 -> 0.016145813 | R4: =shock_L_theta!N4 -> 0.5876596 | S4: =shock_L_theta!N14 -> 0.58765683 | T4: =shock_L_theta!N24 -> 0.58879032 | U4: =shock_L_theta!O4 -> 0.074099257 | V4: =shock_L_theta!O14 -> 0.075073333 | W4: =shock_L_theta!O24 -> 0.075718719 | X4: =shock_L_theta!P4 -> 0.8514658 | Y4: =shock_L_theta!P14 -> 0.85145607 | Z4: =shock_L_theta!P24 -> 0.85544995 | AA4: =shock_L_psi!L4 -> 0.015374375 | AB4: =shock_L_psi!L14 -> 0.015859211 | AC4: =shock_L_psi!L24 -> 0.016211818 | AD4: =shock_L_psi!N4 -> 0.58796737 | AE4: =shock_L_psi!N14 -> 0.58827532 | AF4: =shock_L_psi!N24 -> 0.58937169 | AG4: =shock_L_psi!O4 -> 0.07374875 | AH4: =shock_L_psi!O14 -> 0.074718421 | AI4: =shock_L_psi!O24 -> 0.075423636 | AJ4: =shock_L_psi!P4 -> 0.78812547 | AK4: =shock_L_psi!P14 -> 0.78962231 | AL4: =shock_L_psi!P24 -> 0.79497728 | AM4: =shock_delta!L4 -> 0.015374375 | AN4: =shock_delta!L14 -> 0.015859211 | AO4: =shock_delta!L24 -> 0.016211818 | AP4: =shock_delta!N4 -> 0.59952473 | AQ4: =shock_delta!N14 -> 0.59949407 | AR4: =shock_delta!N24 -> 0.6003387 | AS4: =shock_delta!O4 -> 0.07374875 | AT4: =shock_delta!O14 -> 0.074718421 | AU4: =shock_delta!O24 -> 0.075423636 | AV4: =shock_delta!P4 -> 0.89439356 | AW4: =shock_delta!P14 -> 0.89427938 | AX4: =shock_delta!P24 -> 0.89743193
A5: 0.077 | C5: =shock_L!L5 -> 0.0148325 | D5: =shock_L!L15 -> 0.015478947 | E5: =shock_L!L25 -> 0.015949091 | F5: =shock_L!N5 -> 0.57558789 | G5: =shock_L!N15 -> 0.57607179 | H5: =shock_L!N25 -> 0.57760883 | I5: =shock_L!O5 -> 0.072665 | J5: =shock_L!O15 -> 0.073957895 | K5: =shock_L!O25 -> 0.074898182 | L5: =shock_L!P5 -> 0.81025393 | M5: =shock_L!P15 -> 0.81186077 | N5: =shock_L!P25 -> 0.81698909 | O5: =shock_L_theta!L5 -> 0.014421561 | P5: =shock_L_theta!L15 -> 0.015287407 | Q5: =shock_L_theta!L25 -> 0.015861084 | R5: =shock_L_theta!N5 -> 0.57525538 | S5: =shock_L_theta!N15 -> 0.57529443 | T5: =shock_L_theta!N25 -> 0.57686422 | U5: =shock_L_theta!O5 -> 0.073132342 | V5: =shock_L_theta!O15 -> 0.074431111 | W5: =shock_L_theta!O25 -> 0.075291626 | X5: =shock_L_theta!P5 -> 0.80915191 | Y5: =shock_L_theta!P15 -> 0.80928127 | Z5: =shock_L_theta!P25 -> 0.81450005 | AA5: =shock_L_psi!L5 -> 0.0148325 | AB5: =shock_L_psi!L15 -> 0.015478947 | AC5: =shock_L_psi!L25 -> 0.015949091 | AD5: =shock_L_psi!N5 -> 0.57558789 | AE5: =shock_L_psi!N15 -> 0.57607179 | AF5: =shock_L_psi!N25 -> 0.57760883 | AG5: =shock_L_psi!O5 -> 0.072665 | AH5: =shock_L_psi!O15 -> 0.073957895 | AI5: =shock_L_psi!O25 -> 0.074898182 | AJ5: =shock_L_psi!P5 -> 0.73048895 | AK5: =shock_L_psi!P15 -> 0.73265218 | AL5: =shock_L_psi!P25 -> 0.73957034 | AM5: =shock_delta!L5 -> 0.0148325 | AN5: =shock_delta!L15 -> 0.015478947 | AO5: =shock_delta!L25 -> 0.015949091 | AP5: =shock_delta!N5 -> 0.59068114 | AQ5: =shock_delta!N15 -> 0.59070193 | AR5: =shock_delta!N25 -> 0.59189398 | AS5: =shock_delta!O5 -> 0.072665 | AT5: =shock_delta!O15 -> 0.073957895 | AU5: =shock_delta!O25 -> 0.074898182 | AV5: =shock_delta!P5 -> 0.8621615 | AW5: =shock_delta!P15 -> 0.86223561 | AX5: =shock_delta!P25 -> 0.86649926
A6: 1 | C6: =shock_L!L6 -> 0.014290625 | D6: =shock_L!L16 -> 0.015098684 | E6: =shock_L!L26 -> 0.015686364 | F6: =shock_L!N6 -> 0.56335308 | G6: =shock_L!N16 -> 0.56404713 | H6: =shock_L!N26 -> 0.56605913 | I6: =shock_L!O6 -> 0.07158125 | J6: =shock_L!O16 -> 0.073197368 | K6: =shock_L!O26 -> 0.074372727 | L6: =shock_L!P6 -> 0.77081034 | M6: =shock_L!P16 -> 0.77298865 | N6: =shock_L!P26 -> 0.77934276 | O6: =shock_L_theta!L6 -> 0.013776952 | P6: =shock_L_theta!L16 -> 0.014859259 | Q6: =shock_L_theta!L26 -> 0.015576355 | R6: =shock_L_theta!N6 -> 0.56303225 | S6: =shock_L_theta!N16 -> 0.56313287 | T6: =shock_L_theta!N26 -> 0.56516531 | U6: =shock_L_theta!O6 -> 0.072165428 | V6: =shock_L_theta!O16 -> 0.073788889 | W6: =shock_L_theta!O26 -> 0.074864532 | X6: =shock_L_theta!P6 -> 0.76980577 | Y6: =shock_L_theta!P16 -> 0.77012066 | Z6: =shock_L_theta!P26 -> 0.77651272 | AA6: =shock_L_psi!L6 -> 0.014290625 | AB6: =shock_L_psi!L16 -> 0.015098684 | AC6: =shock_L_psi!L26 -> 0.015686364 | AD6: =shock_L_psi!N6 -> 0.56335308 | AE6: =shock_L_psi!N16 -> 0.56404713 | AF6: =shock_L_psi!N26 -> 0.56605913 | AG6: =shock_L_psi!O6 -> 0.07158125 | AH6: =shock_L_psi!O16 -> 0.073197368 | AI6: =shock_L_psi!O26 -> 0.074372727 | AJ6: =shock_L_psi!P6 -> 0.67805508 | AK6: =shock_L_psi!P16 -> 0.68091704 | AL6: =shock_L_psi!P26 -> 0.68928806 | AM6: =shock_delta!L6 -> 0.014290625 | AN6: =shock_delta!L16 -> 0.015098684 | AO6: =shock_delta!L26 -> 0.015686364 | AP6: =shock_delta!N6 -> 0.58182829 | AQ6: =shock_delta!N16 -> 0.58193123 | AR6: =shock_delta!N26 -> 0.58350293 | AS6: =shock_delta!O6 -> 0.07158125 | AT6: =shock_delta!O16 -> 0.073197368 | AU6: =shock_delta!O26 -> 0.074372727 | AV6: =shock_delta!P6 -> 0.8312611 | AW6: =shock_delta!P16 -> 0.83161287 | AX6: =shock_delta!P26 -> 0.83700558
C7: =shock_L!L7 -> 0.01374875 | D7: =shock_L!L17 -> 0.014718421 | E7: =shock_L!L27 -> 0.015423636 | F7: =shock_L!N7 -> 0.55126042 | G7: =shock_L!N17 -> 0.55219743 | H7: =shock_L!N27 -> 0.55471685 | I7: =shock_L!O7 -> 0.0704975 | J7: =shock_L!O17 -> 0.072436842 | K7: =shock_L!O27 -> 0.073847273 | L7: =shock_L!P7 -> 0.73393854 | M7: =shock_L!P17 -> 0.73672444 | N7: =shock_L!P27 -> 0.74427318 | O7: =shock_L_theta!L7 -> 0.013132342 | P7: =shock_L_theta!L17 -> 0.014431111 | Q7: =shock_L_theta!L27 -> 0.015291626 | R7: =shock_L_theta!N7 -> 0.55098629 | S7: =shock_L_theta!N17 -> 0.55116728 | T7: =shock_L_theta!N27 -> 0.55368716 | U7: =shock_L_theta!O7 -> 0.071198513 | V7: =shock_L_theta!O17 -> 0.073146667 | W7: =shock_L_theta!O27 -> 0.074437438 | X7: =shock_L_theta!P7 -> 0.73312573 | Y7: =shock_L_theta!P17 -> 0.73366228 | Z7: =shock_L_theta!P27 -> 0.7411777 | AA7: =shock_L_psi!L7 -> 0.01374875 | AB7: =shock_L_psi!L17 -> 0.014718421 | AC7: =shock_L_psi!L27 -> 0.015423636 | AD7: =shock_L_psi!N7 -> 0.55126042 | AE7: =shock_L_psi!N17 -> 0.55219743 | AF7: =shock_L_psi!N27 -> 0.55471685 | AG7: =shock_L_psi!O7 -> 0.0704975 | AH7: =shock_L_psi!O17 -> 0.072436842 | AI7: =shock_L_psi!O27 -> 0.073847273 | AJ7: =shock_L_psi!P7 -> 0.63021986 | AK7: =shock_L_psi!P17 -> 0.63379364 | AL7: =shock_L_psi!P27 -> 0.6435107 | AM7: =shock_delta!L7 -> 0.01374875 | AN7: =shock_delta!L17 -> 0.014718421 | AO7: =shock_delta!L27 -> 0.015423636 | AP7: =shock_delta!N7 -> 0.57296615 | AQ7: =shock_delta!N17 -> 0.5731819 | AR7: =shock_delta!N27 -> 0.57516502 | AS7: =shock_delta!O7 -> 0.0704975 | AT7: =shock_delta!O17 -> 0.072436842 | AU7: =shock_delta!O27 -> 0.073847273 | AV7: =shock_delta!P7 -> 0.8016115 | AW7: =shock_delta!P17 -> 0.80231869 | AX7: =shock_delta!P27 -> 0.80885273
C8: =shock_L!L8 -> 0.013206875 | D8: =shock_L!L18 -> 0.014338158 | E8: =shock_L!L28 -> 0.015160909 | F8: =shock_L!N8 -> 0.53930745 | G8: =shock_L!N18 -> 0.54051892 | H8: =shock_L!N28 -> 0.54357646 | I8: =shock_L!O8 -> 0.06941375 | J8: =shock_L!O18 -> 0.071676316 | K8: =shock_L!O28 -> 0.073321818 | L8: =shock_L!P8 -> 0.69939495 | M8: =shock_L!P18 -> 0.70281421 | N8: =shock_L!P28 -> 0.71152454 | O8: =shock_L_theta!L8 -> 0.012487732 | P8: =shock_L_theta!L18 -> 0.014002963 | Q8: =shock_L_theta!L28 -> 0.015006897 | R8: =shock_L_theta!N8 -> 0.53911366 | S8: =shock_L_theta!N18 -> 0.53939297 | T8: =shock_L_theta!N28 -> 0.54242359 | U8: =shock_L_theta!O8 -> 0.070231599 | V8: =shock_L_theta!O18 -> 0.072504444 | W8: =shock_L_theta!O28 -> 0.074010345 | X8: =shock_L_theta!P8 -> 0.69884968 | Y8: =shock_L_theta!P18 -> 0.69963574 | Z8: =shock_L_theta!P28 -> 0.70822658 | AA8: =shock_L_psi!L8 -> 0.013206875 | AB8: =shock_L_psi!L18 -> 0.014338158 | AC8: =shock_L_psi!L28 -> 0.015160909 | AD8: =shock_L_psi!N8 -> 0.53930745 | AE8: =shock_L_psi!N18 -> 0.54051892 | AF8: =shock_L_psi!N28 -> 0.54357646 | AG8: =shock_L_psi!O8 -> 0.06941375 | AH8: =shock_L_psi!O18 -> 0.071676316 | AI8: =shock_L_psi!O28 -> 0.073321818 | AJ8: =shock_L_psi!P8 -> 0.58646557 | AK8: =shock_L_psi!P18 -> 0.59075008 | AL8: =shock_L_psi!P28 -> 0.60171091 | AM8: =shock_delta!L8 -> 0.013206875 | AN8: =shock_delta!L18 -> 0.014338158 | AO8: =shock_delta!L28 -> 0.015160909 | AP8: =shock_delta!N8 -> 0.56409472 | AQ8: =shock_delta!N18 -> 0.56445387 | AR8: =shock_delta!N28 -> 0.56687975 | AS8: =shock_delta!O8 -> 0.06941375 | AT8: =shock_delta!O18 -> 0.071676316 | AU8: =shock_delta!O28 -> 0.073321818 | AV8: =shock_delta!P8 -> 0.77313827 | AW8: =shock_delta!P18 -> 0.77426844 | AX8: =shock_delta!P28 -> 0.78195133
C9: =shock_L!L9 -> 0.012665 | D9: =shock_L!L19 -> 0.013957895 | E9: =shock_L!L29 -> 0.014898182 | F9: =shock_L!N9 -> 0.52749176 | G9: =shock_L!N19 -> 0.5290079 | H9: =shock_L!N29 -> 0.53263262 | I9: =shock_L!O9 -> 0.06833 | J9: =shock_L!O19 -> 0.070915789 | K9: =shock_L!O29 -> 0.072796364 | L9: =shock_L!P9 -> 0.66696579 | M9: =shock_L!P19 -> 0.67103598 | N9: =shock_L!P29 -> 0.68087382 | O9: =shock_L_theta!L9 -> 0.011843123 | P9: =shock_L_theta!L19 -> 0.013574815 | Q9: =shock_L_theta!L29 -> 0.014722167 | R9: =shock_L_theta!N9 -> 0.52741066 | S9: =shock_L_theta!N19 -> 0.52780538 | T9: =shock_L_theta!N29 -> 0.53136864 | U9: =shock_L_theta!O9 -> 0.069264684 | V9: =shock_L_theta!O19 -> 0.071862222 | W9: =shock_L_theta!O29 -> 0.073583251 | X9: =shock_L_theta!P9 -> 0.6667488 | Y9: =shock_L_theta!P19 -> 0.6678056 | Z9: =shock_L_theta!P29 -> 0.67742597 | AA9: =shock_L_psi!L9 -> 0.012665 | AB9: =shock_L_psi!L19 -> 0.013957895 | AC9: =shock_L_psi!L29 -> 0.014898182 | AD9: =shock_L_psi!N9 -> 0.52749176 | AE9: =shock_L_psi!N19 -> 0.5290079 | AF9: =shock_L_psi!N29 -> 0.53263262 | AG9: =shock_L_psi!O9 -> 0.06833 | AH9: =shock_L_psi!O19 -> 0.070915789 | AI9: =shock_L_psi!O29 -> 0.072796364 | AJ9: =shock_L_psi!P9 -> 0.54634629 | AK9: =shock_L_psi!P19 -> 0.55133004 | AL9: =shock_L_psi!P29 -> 0.56343747 | AM9: =shock_delta!L9 -> 0.012665 | AN9: =shock_delta!L19 -> 0.013957895 | AO9: =shock_delta!L29 -> 0.014898182 | AP9: =shock_delta!N9 -> 0.55521397 | AQ9: =shock_delta!N19 -> 0.55574705 | AR9: =shock_delta!N29 -> 0.55864663 | AS9: =shock_delta!O9 -> 0.06833 | AT9: =shock_delta!O19 -> 0.070915789 | AU9: =shock_delta!O29 -> 0.072796364 | AV9: =shock_delta!P9 -> 0.74577275 | AW9: =shock_delta!P19 -> 0.74738454 | AX9: =shock_delta!P29 -> 0.75621974
C10: Change | O10: Change | AA10: Change | AM10: Change
C11: =100*(C3-$A$3) -> -0.108375 | D11: =100*(D3-$A$3) -> -0.076052632 | E11: =100*(E3-$A$3) -> -0.052545455 | F11: =100*(F3-$A$4) -> -2.5505884 | G11: =100*(G3-$A$4) -> -2.5338244 | H11: =100*(H3-$A$4) -> -2.4646314 | I11: =100*(I3-$A$5) -> -0.21675 | J11: =100*(J3-$A$5) -> -0.15210526 | K11: =100*(K3-$A$5) -> -0.10509091 | L11: =LN(L3/1) -> -0.10757022 | M11: =LN(M3/1) -> -0.10687139 | N11: =LN(N3/1) -> -0.10398591 | O11: =100*(O3-$A$3) -> -0.12892193 | P11: =100*(P3-$A$3) -> -0.08562963 | Q11: =100*(Q3-$A$3) -> -0.056945813 | R11: =100*(R3-$A$4) -> -2.5751031 | S11: =100*(S3-$A$4) -> -2.5774932 | T11: =100*(T3-$A$4) -> -2.5049689 | U11: =100*(U3-$A$5) -> -0.1933829 | V11: =100*(V3-$A$5) -> -0.12844444 | W11: =100*(W3-$A$5) -> -0.085418719 | X11: =LN(X3/1) -> -0.10859199 | Y11: =LN(Y3/1) -> -0.10869159 | Z11: =LN(Z3/1) -> -0.10566826 | AA11: =100*(AA3-$A$3) -> -0.108375 | AB11: =100*(AB3-$A$3) -> -0.076052632 | AC11: =100*(AC3-$A$3) -> -0.052545455 | AD11: =100*(AD3-$A$4) -> -2.5505884 | AE11: =100*(AE3-$A$4) -> -2.5338244 | AF11: =100*(AF3-$A$4) -> -2.4646314 | AG11: =100*(AG3-$A$5) -> -0.21675 | AH11: =100*(AH3-$A$5) -> -0.15210526 | AI11: =100*(AI3-$A$5) -> -0.10509091 | AJ11: =LN(AJ3/1) -> -0.16055257 | AK11: =LN(AK3/1) -> -0.15950953 | AL11: =LN(AL3/1) -> -0.15520285 | AM11: =100*(AM3-$A$3) -> -0.108375 | AN11: =100*(AN3-$A$3) -> -0.076052632 | AO11: =100*(AO3-$A$3) -> -0.052545455 | AP11: =100*(AP3-$A$4) -> -1.7640947 | AQ11: =100*(AQ3-$A$4) -> -1.7692252 | AR11: =100*(AR3-$A$4) -> -1.7162407 | AS11: =100*(AS3-$A$5) -> -0.21675 | AT11: =100*(AT3-$A$5) -> -0.15210526 | AU11: =100*(AU3-$A$5) -> -0.10509091 | AV11: =LN(AV3/1) -> -0.074674785 | AW11: =LN(AW3/1) -> -0.074890113 | AX11: =LN(AX3/1) -> -0.072665855
C12: =100*(C4-$A$3) -> -0.1625625 | D12: =100*(D4-$A$3) -> -0.11407895 | E12: =100*(E4-$A$3) -> -0.078818182 | F12: =100*(F4-$A$4) -> -3.8032625 | G12: =100*(G4-$A$4) -> -3.7724675 | H12: =100*(H4-$A$4) -> -3.6628306 | I12: =100*(I4-$A$5) -> -0.325125 | J12: =100*(J4-$A$5) -> -0.22815789 | K12: =100*(K4-$A$5) -> -0.15763636 | L12: =LN(L4/1) -> -0.15952565 | M12: =LN(M4/1) -> -0.15825436 | N12: =LN(N4/1) -> -0.15372597 | O12: =100*(O4-$A$3) -> -0.1933829 | P12: =100*(P4-$A$3) -> -0.12844444 | Q12: =100*(Q4-$A$3) -> -0.085418719 | R12: =100*(R4-$A$4) -> -3.8340403 | S12: =100*(S4-$A$4) -> -3.8343172 | T12: =100*(T4-$A$4) -> -3.7209677 | U12: =100*(U4-$A$5) -> -0.29007435 | V12: =100*(V4-$A$5) -> -0.19266667 | W12: =100*(W4-$A$5) -> -0.12812808 | X12: =LN(X4/1) -> -0.16079594 | Y12: =LN(Y4/1) -> -0.16080737 | Z12: =LN(Z4/1) -> -0.15612769 | AA12: =100*(AA4-$A$3) -> -0.1625625 | AB12: =100*(AB4-$A$3) -> -0.11407895 | AC12: =100*(AC4-$A$3) -> -0.078818182 | AD12: =100*(AD4-$A$4) -> -3.8032625 | AE12: =100*(AE4-$A$4) -> -3.7724675 | AF12: =100*(AF4-$A$4) -> -3.6628306 | AG12: =100*(AG4-$A$5) -> -0.325125 | AH12: =100*(AH4-$A$5) -> -0.22815789 | AI12: =100*(AI4-$A$5) -> -0.15763636 | AJ12: =LN(AJ4/1) -> -0.23809798 | AK12: =LN(AK4/1) -> -0.23620053 | AL12: =LN(AL4/1) -> -0.22944175 | AM12: =100*(AM4-$A$3) -> -0.1625625 | AN12: =100*(AN4-$A$3) -> -0.11407895 | AO12: =100*(AO4-$A$3) -> -0.078818182 | AP12: =100*(AP4-$A$4) -> -2.6475274 | AQ12: =100*(AQ4-$A$4) -> -2.6505927 | AR12: =100*(AR4-$A$4) -> -2.5661298 | AS12: =100*(AS4-$A$5) -> -0.325125 | AT12: =100*(AT4-$A$5) -> -0.22815789 | AU12: =100*(AU4-$A$5) -> -0.15763636 | AV12: =LN(AV4/1) -> -0.11160938 | AW12: =LN(AW4/1) -> -0.11173705 | AX12: =LN(AX4/1) -> -0.10821801
C13: =100*(C5-$A$3) -> -0.21675 | D13: =100*(D5-$A$3) -> -0.15210526 | E13: =100*(E5-$A$3) -> -0.10509091 | F13: =100*(F5-$A$4) -> -5.0412111 | G13: =100*(G5-$A$4) -> -4.9928211 | H13: =100*(H5-$A$4) -> -4.8391174 | I13: =100*(I5-$A$5) -> -0.4335 | J13: =100*(J5-$A$5) -> -0.30421053 | K13: =100*(K5-$A$5) -> -0.21018182 | L13: =LN(L5/1) -> -0.21040758 | M13: =LN(M5/1) -> -0.20842642 | N13: =LN(N5/1) -> -0.20212954 | O13: =100*(O5-$A$3) -> -0.25784387 | P13: =100*(P5-$A$3) -> -0.17125926 | Q13: =100*(Q5-$A$3) -> -0.11389163 | R13: =100*(R5-$A$4) -> -5.0744623 | S13: =100*(S5-$A$4) -> -5.0705566 | T13: =100*(T5-$A$4) -> -4.9135785 | U13: =100*(U5-$A$5) -> -0.3867658 | V13: =100*(V5-$A$5) -> -0.25688889 | W13: =100*(W5-$A$5) -> -0.17083744 | X13: =LN(X5/1) -> -0.2117686 | Y13: =LN(Y5/1) -> -0.21160875 | Z13: =LN(Z5/1) -> -0.20518079 | AA13: =100*(AA5-$A$3) -> -0.21675 | AB13: =100*(AB5-$A$3) -> -0.15210526 | AC13: =100*(AC5-$A$3) -> -0.10509091 | AD13: =100*(AD5-$A$4) -> -5.0412111 | AE13: =100*(AE5-$A$4) -> -4.9928211 | AF13: =100*(AF5-$A$4) -> -4.8391174 | AG13: =100*(AG5-$A$5) -> -0.4335 | AH13: =100*(AH5-$A$5) -> -0.30421053 | AI13: =100*(AI5-$A$5) -> -0.21018182 | AJ13: =LN(AJ5/1) -> -0.31404117 | AK13: =LN(AK5/1) -> -0.3110842 | AL13: =LN(AL5/1) -> -0.30168588 | AM13: =100*(AM5-$A$3) -> -0.21675 | AN13: =100*(AN5-$A$3) -> -0.15210526 | AO13: =100*(AO5-$A$3) -> -0.10509091 | AP13: =100*(AP5-$A$4) -> -3.5318856 | AQ13: =100*(AQ5-$A$4) -> -3.5298074 | AR13: =100*(AR5-$A$4) -> -3.4106016 | AS13: =100*(AS5-$A$5) -> -0.4335 | AT13: =100*(AT5-$A$5) -> -0.30421053 | AU13: =100*(AU5-$A$5) -> -0.21018182 | AV13: =LN(AV5/1) -> -0.14831267 | AW13: =LN(AW5/1) -> -0.14822672 | AX13: =LN(AX5/1) -> -0.14329402
C14: =100*(C6-$A$3) -> -0.2709375 | D14: =100*(D6-$A$3) -> -0.19013158 | E14: =100*(E6-$A$3) -> -0.13136364 | F14: =100*(F6-$A$4) -> -6.2646924 | G14: =100*(G6-$A$4) -> -6.1952873 | H14: =100*(H6-$A$4) -> -5.9940874 | I14: =100*(I6-$A$5) -> -0.541875 | J14: =100*(J6-$A$5) -> -0.38026316 | K14: =100*(K6-$A$5) -> -0.26272727 | L14: =LN(L6/1) -> -0.26031292 | M14: =LN(M6/1) -> -0.25749092 | N14: =LN(N6/1) -> -0.24930433 | O14: =100*(O6-$A$3) -> -0.32230483 | P14: =100*(P6-$A$3) -> -0.21407407 | Q14: =100*(Q6-$A$3) -> -0.14236453 | R14: =100*(R6-$A$4) -> -6.2967746 | S14: =100*(S6-$A$4) -> -6.286713 | T14: =100*(T6-$A$4) -> -6.0834695 | U14: =100*(U6-$A$5) -> -0.48345725 | V14: =100*(V6-$A$5) -> -0.32111111 | W14: =100*(W6-$A$5) -> -0.2135468 | X14: =LN(X6/1) -> -0.26161704 | Y14: =LN(Y6/1) -> -0.26120807 | Z14: =LN(Z6/1) -> -0.25294226 | AA14: =100*(AA6-$A$3) -> -0.2709375 | AB14: =100*(AB6-$A$3) -> -0.19013158 | AC14: =100*(AC6-$A$3) -> -0.13136364 | AD14: =100*(AD6-$A$4) -> -6.2646924 | AE14: =100*(AE6-$A$4) -> -6.1952873 | AF14: =100*(AF6-$A$4) -> -5.9940874 | AG14: =100*(AG6-$A$5) -> -0.541875 | AH14: =100*(AH6-$A$5) -> -0.38026316 | AI14: =100*(AI6-$A$5) -> -0.26272727 | AJ14: =LN(AJ6/1) -> -0.38852675 | AK14: =LN(AK6/1) -> -0.3843148 | AL14: =LN(AL6/1) -> -0.37209601 | AM14: =100*(AM6-$A$3) -> -0.2709375 | AN14: =100*(AN6-$A$3) -> -0.19013158 | AO14: =100*(AO6-$A$3) -> -0.13136364 | AP14: =100*(AP6-$A$4) -> -4.4171709 | AQ14: =100*(AQ6-$A$4) -> -4.4068772 | AR14: =100*(AR6-$A$4) -> -4.2497075 | AS14: =100*(AS6-$A$5) -> -0.541875 | AT14: =100*(AT6-$A$5) -> -0.38026316 | AU14: =100*(AU6-$A$5) -> -0.26272727 | AV14: =LN(AV6/1) -> -0.18481134 | AW14: =LN(AW6/1) -> -0.18438824 | AX14: =LN(AX6/1) -> -0.17792455
C15: =100*(C7-$A$3) -> -0.325125 | D15: =100*(D7-$A$3) -> -0.22815789 | E15: =100*(E7-$A$3) -> -0.15763636 | F15: =100*(F7-$A$4) -> -7.4739584 | G15: =100*(G7-$A$4) -> -7.3802566 | H15: =100*(H7-$A$4) -> -7.1283148 | I15: =100*(I7-$A$5) -> -0.65025 | J15: =100*(J7-$A$5) -> -0.45631579 | K15: =100*(K7-$A$5) -> -0.31527273 | L15: =LN(L7/1) -> -0.30932998 | M15: =LN(M7/1) -> -0.30554135 | N15: =LN(N7/1) -> -0.29534713 | O15: =100*(O7-$A$3) -> -0.3867658 | P15: =100*(P7-$A$3) -> -0.25688889 | Q15: =100*(Q7-$A$3) -> -0.17083744 | R15: =100*(R7-$A$4) -> -7.501371 | S15: =100*(S7-$A$4) -> -7.4832719 | T15: =100*(T7-$A$4) -> -7.2312838 | U15: =100*(U7-$A$5) -> -0.5801487 | V15: =100*(V7-$A$5) -> -0.38533333 | W15: =100*(W7-$A$5) -> -0.25625616 | X15: =LN(X7/1) -> -0.31043807 | Y15: =LN(Y7/1) -> -0.30970647 | Z15: =LN(Z7/1) -> -0.29951487 | AA15: =100*(AA7-$A$3) -> -0.325125 | AB15: =100*(AB7-$A$3) -> -0.22815789 | AC15: =100*(AC7-$A$3) -> -0.15763636 | AD15: =100*(AD7-$A$4) -> -7.4739584 | AE15: =100*(AE7-$A$4) -> -7.3802566 | AF15: =100*(AF7-$A$4) -> -7.1283148 | AG15: =100*(AG7-$A$5) -> -0.65025 | AH15: =100*(AH7-$A$5) -> -0.45631579 | AI15: =100*(AI7-$A$5) -> -0.31527273 | AJ15: =LN(AJ7/1) -> -0.46168654 | AK15: =LN(AK7/1) -> -0.45603187 | AL15: =LN(AL7/1) -> -0.44081662 | AM15: =100*(AM7-$A$3) -> -0.325125 | AN15: =100*(AN7-$A$3) -> -0.22815789 | AO15: =100*(AO7-$A$3) -> -0.15763636 | AP15: =100*(AP7-$A$4) -> -5.3033846 | AQ15: =100*(AQ7-$A$4) -> -5.2818099 | AR15: =100*(AR7-$A$4) -> -5.0834985 | AS15: =100*(AS7-$A$5) -> -0.65025 | AT15: =100*(AT7-$A$5) -> -0.45631579 | AU15: =100*(AU7-$A$5) -> -0.31527273 | AV15: =LN(AV7/1) -> -0.2211312 | AW15: =LN(AW7/1) -> -0.22024938 | AX15: =LN(AX7/1) -> -0.21213841
C16: =100*(C8-$A$3) -> -0.3793125 | D16: =100*(D8-$A$3) -> -0.26618421 | E16: =100*(E8-$A$3) -> -0.18390909 | F16: =100*(F8-$A$4) -> -8.6692555 | G16: =100*(G8-$A$4) -> -8.548108 | H16: =100*(H8-$A$4) -> -8.2423535 | I16: =100*(I8-$A$5) -> -0.758625 | J16: =100*(J8-$A$5) -> -0.53236842 | K16: =100*(K8-$A$5) -> -0.36781818 | L16: =LN(L8/1) -> -0.35753968 | M16: =LN(M8/1) -> -0.3526627 | N16: =LN(N8/1) -> -0.34034537 | O16: =100*(O8-$A$3) -> -0.45122677 | P16: =100*(P8-$A$3) -> -0.2997037 | Q16: =100*(Q8-$A$3) -> -0.19931034 | R16: =100*(R8-$A$4) -> -8.6886338 | S16: =100*(S8-$A$4) -> -8.6607031 | T16: =100*(T8-$A$4) -> -8.3576406 | U16: =100*(U8-$A$5) -> -0.67684015 | V16: =100*(V8-$A$5) -> -0.44955556 | W16: =100*(W8-$A$5) -> -0.29896552 | X16: =LN(X8/1) -> -0.35831961 | Y16: =LN(Y8/1) -> -0.35719545 | Z16: =LN(Z8/1) -> -0.34499122 | AA16: =100*(AA8-$A$3) -> -0.3793125 | AB16: =100*(AB8-$A$3) -> -0.26618421 | AC16: =100*(AC8-$A$3) -> -0.18390909 | AD16: =100*(AD8-$A$4) -> -8.6692555 | AE16: =100*(AE8-$A$4) -> -8.548108 | AF16: =100*(AF8-$A$4) -> -8.2423535 | AG16: =100*(AG8-$A$5) -> -0.758625 | AH16: =100*(AH8-$A$5) -> -0.53236842 | AI16: =100*(AI8-$A$5) -> -0.36781818 | AJ16: =LN(AJ8/1) -> -0.53364131 | AK16: =LN(AK8/1) -> -0.52636223 | AL16: =LN(AL8/1) -> -0.50797817 | AM16: =100*(AM8-$A$3) -> -0.3793125 | AN16: =100*(AN8-$A$3) -> -0.26618421 | AO16: =100*(AO8-$A$3) -> -0.18390909 | AP16: =100*(AP8-$A$4) -> -6.1905282 | AQ16: =100*(AQ8-$A$4) -> -6.1546133 | AR16: =100*(AR8-$A$4) -> -5.912025 | AS16: =100*(AS8-$A$5) -> -0.758625 | AT16: =100*(AT8-$A$5) -> -0.53236842 | AU16: =100*(AU8-$A$5) -> -0.36781818 | AV16: =LN(AV8/1) -> -0.25729737 | AW16: =LN(AW8/1) -> -0.25583664 | AX16: =LN(AX8/1) -> -0.24596278
